Workbook
Name xadd1: 'Conveyance Voucher'!#REF!

Sheet Front Page
A1: Ranks Petroleum Limited
A2: Petty Cash Bill Breakdown | C2: Bill Duration | D2: 11.01.2026- 20.01.2026
A3: WH/Depot | B3: Cumilla | C3: Month: january -2026 | D3: Bill No: Cum/105/january '2026
A4: Sl. No. | B4: Purpose | C4: Amount (Tk.) | D4: Purpose
A5: 1 | B5: B2B- IPP | C5: ='1. B2B- IPP'!M4 -> 0
A6: 2 | B6: B2C | C6: ='2. B2C'!L4 -> 6330 | D6: Cost: Transport,,Food,Conveyance
A7: 3 | B7: B2B- Non Power | C7: ='3. B2B-Non Power'!L4 -> 0
A8: 4 | B8: Goods Transfer (Sending) | C8: ='4. Goods Sending Expense'!L4 -> 2620 | D8: Cost: Conveyance,food
A9: 5 | B9: Goods Transfer (Receiving) | C9: ='5. Goods Receiving Expense'!L4 -> 340 | D9: Cost: Conveyance,food
A10: 6 | B10: Warehouse Maintenance | C10: ='6.WH-Depot Maintenance'!D3 -> 400 | D10: courier
A11: 7 | B11: Utilities | C11: ='7. Utilities'!F2 -> 772 | D11: Electricity bill,water bill
A12: 8 | B12: Printing | C12: ='8. Printing'!E2 -> 0
A13: 9 | B13: Stationary | C13: ='9. Stationary'!E2 -> 0
A14: 10 | B14: Delivery Van Fuel & Lubricant | C14: ='10-11.Delivery Van Expense'!D2 -> 0
A15: 11 | B15: Delivery Van Maintenance | C15: ='10-11.Delivery Van Expense'!D13 -> 0
A16: 12 | B16: Entertainment | C16: ='12. Entertainment'!D2 -> 0
A17: 13 | B17: Food Allowance | C17: ='13. Food Allowance'!D2 -> 0
A18: 14 | B18: Conveyance | C18: ='14. Conveyance'!D2 -> 50 | D18: WH to WH, WH to HO, WH to Shop etc.
A19: 15 | B19: Holiday Expense | C19: ='15. For Security'!D2 -> 2200 | D19: We are working on a government holiday
B20: Total | C20: =SUM(C5:C19) -> 12712
C22: Unit | D22: Litre (L)
C23: B2B-IPP | D23: ='1. B2B- IPP'!D4 -> 0
C24: B2C | D24: ='2. B2C'!D4 -> 752
C25: B2B-Non Power | D25: ='3. B2B-Non Power'!D4 -> 0
C26: Goods Transfer (Sending) | D26: ='4. Goods Sending Expense'!D4 -> 327
C27: Goods Import (Receiving) | D27: ='5. Goods Receiving Expense'!D4 -> 240
C28: Total (L) | D28: =SUM(D23:D27) -> 1319
A37: Prepared By | B37: Checked By | C37: Line Manager | D37: Head of SCM
C43: _______________
A44: Dept. of F&A | C44: Internal Audit | D44: Approved By

Sheet 1. B2B- IPP
C1: B2B - IPP
H2: Delivey Person's Expense
A3: Date | B3: DO No. | C3: Customer Name | D3: Volume (L) | E3: Delivery Vehicle Charge (Tk.) | F3: Courier Charge (Tk.) | G3: Labour Charge | H3: Helper Name | I3: Conveyance | J3: Hotel Rent | K3: Food | L3: Others | M3: Total
D4: =SUM(D5:D100) -> 0 | E4: =SUM(E5:E100) -> 0 | F4: =SUM(F5:F100) -> 0 | G4: =SUM(G5:G100) -> 0 | H4: =SUM(H5:H100) -> 0 | I4: =SUM(I5:I100) -> 0 | J4: =SUM(J5:J100) -> 0 | K4: =SUM(K5:K100) -> 0 | L4: =SUM(L5:L100) -> 0 | M4: =SUM(E4,F4,G4,I4,J4,K4,L4) -> 0

Sheet 2. B2C
A1: B2C
G2: Delivey Person's Expense
A3: Date | B3: DO No. | C3: Customer Name | D3: Volume (L) | E3: Labour Cost | F3: Transport Cost | G3: Executive & Helper Name | H3: Helper Conveyance | I3: Hotel Rent | J3: Food | K3: Others | L3: Total
D4: =SUM(D5:D95) -> 752 | E4: =SUM(E6:E10) -> 0 | F4: =SUM(F5:F95) -> 4510 | H4: =SUM(H5:H95) -> 1820 | I4: =SUM(I6:I10) -> 0 | J4: =SUM(J6:J108) -> 0 | K4: =SUM(K6:K10) -> 0 | L4: =SUM(E4,F4,H4,I4,J4,) -> 6330
A5: 46033 | B5: 098067 | C5: Sami Sadi Engineering | D5: 30 | F5: 150 | G5: rafi | H5: 100 | L5: =SUM(F5:H5) -> 250
A6: 46034 | B6: 98022 | C6: Nitol Motors Ltd. | D6: 120 | F6: 270 | G6: shah alam | H6: 30 | L6: =SUM(F6:H6) -> 300
A7: 46035 | B7: 98160 | C7: Jibon Honda Workshop | D7: 171 | F7: 1050 | G7: shah alam | H7: 200 | L7: =SUM(F7:H7) -> 1250
A8: 46035 | B8: 98184 | C8: Polash Honda Servicing Center | D8: 13 | F8: 30 | G8: rafi | H8: 30 | L8: =SUM(F8:H8) -> 60
A9: 46036 | B9: 98260 | C9: Sami Sadi Engineering | D9: 13 | F9: 100 | G9: rafi | H9: 100 | L9: =SUM(F9:H9) -> 200
A10: 46036 | B10: 98261 | C10: Nozir Motors | D10: 27 | F10: 250 | G10: shah alam | H10: 200 | L10: =SUM(F10:H10) -> 450
A11: 46039 | B11: 098369 | C11: Al-Amin Tyre & Battery Shop | D11: 12 | F11: 60 | G11: rafi | H11: 60 | L11: =SUM(F11:H11) -> 120
A12: 46040 | B12: 098368 | C12: M/S Bhuiyan Traders | D12: 27 | F12: 1150 | G12: shah alam & rafi | H12: 550 | L12: =SUM(F12:H12) -> 1700
A13: 46040 | B13: 098333 | C13: Sanjit Engenering Workshop | D13: 79 | L13: =SUM(F13:H13) -> 0
A14: 46040 | B14: 098375 | C14: Predesh Motors | D14: 12 | L14: =SUM(F14:H14) -> 0
A15: 46041 | B15: 98424 | C15: Hondha Auto King | D15: 13 | F15: 350 | G15: shah alam | H15: 200 | L15: =SUM(F15:H15) -> 550
A16: 46041 | B16: 98425 | C16: Basar Traders | D16: 4 | L16: =SUM(F16:H16) -> 0
A17: 46041 | B17: 98426 | C17: Arju motors | D17: 8 | L17: =SUM(F17:H17) -> 0
A18: 46041 | B18: 98441 | C18: Sami Sadi Engineering | D18: 13 | F18: 100 | G18: rafi | H18: 100 | L18: =SUM(F18:H18) -> 200
A19: 46041 | B19: 98452 | C19: M/S Tamanna Machinery | D19: 210 | F19: 1000 | G19: shah alam & rafi | H19: 250 | L19: =SUM(F19:H19) -> 1250
L20: =SUM(F20:H20) -> 0
L21: =SUM(F21:H21) -> 0
L42: =SUM(F42+H42) -> 0
L43: =SUM(F43+H43) -> 0
L44: =SUM(F44+H44) -> 0
L45: =SUM(F45+H45) -> 0
L46: =SUM(F46+H46) -> 0
L47: =SUM(F47+H47) -> 0
L48: =SUM(F48+H48) -> 0
L49: =SUM(F49+H49) -> 0
L50: =SUM(F50+H50) -> 0

Sheet 3. B2B-Non Power
A1: B2B Non Power
G2: Delivey Person's Expense
A3: Date | B3: DO No. | C3: Customer Name | D3: Volume (L) | E3: Labour Cost | F3: Transport Cost | G3: Helper Name | H3: Helper Conveyance | I3: Hotel Rent | J3: Food | K3: Others | L3: Total
D4: =SUM(D5:D100) -> 0 | E4: =SUM(E5:E100) -> 0 | F4: =SUM(F5:F100) -> 0 | H4: =SUM(H5:H100) -> 0 | I4: =SUM(I5:I100) -> 0 | J4: =SUM(J5:J100) -> 0 | K4: =SUM(K5:K100) -> 0 | L4: =SUM(H4:K4,F4,E4) -> 0

Sheet Goods Delivery Voucher
A1: Ranks Petroleum Limited | I1: Ranks Petroleum Limited
A3: Employee Name: | C3: rafi,sohel,arif,shah alam | F3: Position: | G3: Helper | I3: Employee Name: | K3: Palash | N3: Position: | O3: Helper
A5: Sl. No. | B5: Date | C5: From | D5: To | E5: Purpose/DO | F5: Via | G5: Amount | I5: Sl. No. | J5: Date | K5: From | L5: To | M5: Purpose/DO | N5: Via | O5: Amount
A6: 1 | B6: 46033 | C6: depot | D6: Gowripur Bus stand, daudkandi, comilla | E6: delivery | F6: auto/bus | G6: 150
A7: =SUM(A6+1) -> 2 | B7: 46034 | C7: depot | D7: Mynamoti Cumilla | E7: delivery | F7: auto/bus/cng | G7: 270
A8: =SUM(A7+1) -> 3 | B8: 46035 | C8: depot | D8: Raster Matha,Senbagh,Noakhali. | E8: delivery | F8: auto/bus/cng | G8: 1050
A9: =SUM(A8+1) -> 4 | B9: 46036 | C9: depot | D9: Nazira Bazar, Cumilla | E9: delivery | F9: auto/bus/cng | G9: 30
A10: =SUM(A9+1) -> 5 | B10: 46036 | C10: depot | D10: Gowripur Bus stand, daudkandi, comilla | E10: delivery | F10: auto/bus/cng | G10: 100
A11: =SUM(A10+1) -> 6 | B11: 46036 | C11: depot | D11: east bazar,Chatkhil,Noakhali | E11: delivery | F11: auto/bus/cng | G11: 250
A12: =SUM(A11+1) -> 7 | B12: 46039 | C12: depot | D12: Voroshar bazar, Burichong, cumilla | E12: delivery | F12: auto | G12: 60
A13: =SUM(A12+1) -> 8 | B13: 46040 | C13: depot | D13: Bishwaroad more, B.Baria sadar, B.baria,Nasirnagar b.baria, Bangora Bazar (Ramjan Molla Masjid), Nabinagar, | E13: delivery | F13: auto/bus/cng | G13: 1150
A14: =SUM(A13+1) -> 9 | B14: 46041 | C14: depot | D14: Senbug rastarmatha, senbug,Noakhali,hospital road, senbag,Noakhali | E14: delivery | F14: auto/bus/cng | G14: 350
A15: =SUM(A14+1) -> 10 | B15: 46041 | C15: depot | D15: Gowripur Bus stand, daudkandi, comilla | E15: delivery | F15: auto/bus/cng | G15: 100
A16: 11 | B16: 46041 | C16: depot | D16: Dohabanga,Sharashti get,Sharashti | E16: delivery | F16: auto/bus/cng | G16: 1000
F18: Total | G18: =SUM(G6:G16) -> 4510
I20: …................. | L20: …..................... | N20: …......................
I21: Prepared By | L21: In-charge | N21: Checked By
A22: …................. | D22: …..................... | F22: …......................
A23: Prepared By | D23: In-charge | F23: Checked By

Sheet Conveyance Voucher
A1: Ranks Petroleum Limited | I1: Ranks Petroleum Limited
A3: Employee Name: | C3: shah alam & sohel & rafi | F3: Position: | G3: Helper | I3: Employee Name: | K3: arif | N3: Position: | O3: Executive
A5: Sl. No. | B5: Date | C5: From | D5: To | E5: Purpose | F5: Via | G5: Amount | I5: Sl. No. | J5: Date | K5: From | L5: To | M5: Purpose | N5: Via | O5: Amount
A6: 1 | B6: 46040 | C6: angora Bazar (Ramjan Molla Masjid), Nabinagar,,Nasirnagar b.baria, | D6: depot | E6: delivery | F6: bus,auto,cng | G6: 550 | I6: 1 | J6: 44964 | K6: shoyagazi,cumilla | L6: depot | M6: delivery | N6: bus,auto | O6: 60
A7: 2 | B7: 46041 | C7: Dohabanga,Sharashti get,Sharashti | D7: depot | E7: delivery | F7: bus,auto,cng | G7: 250 | N7: Total | O7: =SUM(O6:O6) -> 60
I9: …................. | L9: …..................... | N9: …......................
F10: Total | G10: =SUM(G6:G7) -> 800 | I10: Prepared By | L10: In-charge | N10: Checked By
A12: …................. | D12: …..................... | F12: …...................... | I12: Ranks Petroleum Limited
A13: Prepared By | D13: In-charge | F13: Checked By
I14: Employee Name: | K14: dipok | N14: Position: | O14: Helper
A15: Ranks Petroleum Limited
I16: Sl. No. | J16: Date | K16: From | L16: To | M16: Purpose | N16: Via | O16: Amount
A17: Employee Name: | C17: rafi | F17: Position: | G17: helper | I17: 1 | J17: 45202 | K17: b-bariya,tinlack pir,kosba | L17: depot | M17: delivery | N17: bus,auto,cng
I18: 2 | J18: 45203 | K18: police fari cumilla | L18: depot | M18: delivery | N18: auto
A19: Sl. No. | B19: Date | C19: From | D19: To | E19: Purpose | F19: Via | G19: Amount
A20: 1 | B20: 46033 | C20: Gowripur Bus stand, daudkandi, comilla | D20: depot | E20: delivery | F20: bus,auto | G20: 100 | N20: Total
A21: 2 | B21: 46035 | C21: Nazira Bazar, Cumilla | D21: depot | E21: delivery | F21: bus,auto | G21: 30
A22: 3 | B22: 46036 | C22: Gowripur Bus stand, daudkandi, comilla | D22: depot | E22: delivery | F22: bus,auto | G22: 100
A23: 4 | B23: 46039 | C23: Voroshar bazar, Burichong, cumilla | D23: depot | E23: delivery | F23: bus,auto | G23: 60
A24: 5 | B24: 46041 | C24: Gowripur Bus stand, daudkandi, comilla | D24: depot | E24: delivery | F24: bus,auto | G24: 100
I25: Prepared By | L25: In-charge | N25: Checked By
F26: Total | G26: =SUM(G20:G24) -> 390
I28: Ranks Petroleum Limited
A29: …................. | D29: …..................... | F29: …...................... | I29: conveyance
A30: Prepared By | D30: In-charge | F30: Checked By | I30: Employee Name: | K30: arif | N30: Position: | O30: Executive
A32: Ranks Petroleum Limited | I32: Sl. No. | J32: Date | K32: From | L32: To | M32: Purpose | N32: Via | O32: Amount
I33: 1
A34: Employee Name: | C34: shah alam | F34: Position: | G34: Helper | I34: 2
A36: Sl. No. | B36: Date | C36: From | D36: To | E36: Purpose | F36: Via | G36: Amount
A37: 1 | B37: 46034 | C37: Mynamoti Cumilla | D37: depot | E37: delivery | F37: bus,auto | G37: 30
A38: 2 | B38: 46035 | C38: Raster Matha,Senbagh,Noakhali. | D38: depot | E38: delivery | F38: bus,auto,cng | G38: 200 | N38: Total | O38: =SUM(O33:O36) -> 0
A39: 3 | B39: 46036 | C39: east bazar,Chatkhil,Noakhali | D39: depot | E39: delivery | F39: bus,auto,cng | G39: 200
A40: 4 | B40: 46041 | C40: hospital road, senbag,Noakhali | D40: depot | E40: delivery | F40: bus,auto,cng | G40: 200
F42: Total | G42: =SUM(G37:G41) -> 630 | I42: …................. | L42: …..................... | N42: …......................
I43: Prepared By | L43: In-charge | N43: Checked By
A45: …................. | D45: …..................... | F45: …......................
A46: Prepared By | D46: In-charge | F46: Checked By
A48: Ranks Petroleum Limited
A50: Employee Name: | C50: arif | F50: Position: | G50: Executive
A52: Sl. No. | B52: Date | C52: From | D52: To | E52: Purpose | F52: Via | G52: Amount
...

Sheet 4. Goods Sending Expense
A1: Goods Transfer_Sending
G2: Delivey Person's Expense
A3: Date | B3: TO No. | C3: Customer Name | D3: Volume (L) | E3: Labour Cost | F3: Transport Cost | G3: Helper Name | H3: Helper Conveyance | I3: Hotel Rent | J3: Food | K3: Others | L3: Total
D4: =SUM(D5:D100) -> 327 | E4: =SUM(E5:E100) -> 0 | F4: =SUM(F5:F100) -> 2200 | H4: =SUM(H5:H100) -> 420 | I4: =SUM(I5:I100) -> 0 | J4: =SUM(J5:J100) -> 0 | K4: =SUM(K5:K100) -> 0 | L4: =SUM(E4,F4,H4,I4,J4,K4) -> 2620
A5: 46034 | B5: 10925 | C5: ulukhola warehouse | D5: 20 | F5: 200 | G5: shah alam | H5: 120
A6: 46042 | B6: 10904 | C6: ulukhola warehouse | D6: 307 | F6: 2000 | G6: shah alam & sohel | H6: 300

Sheet 5. Goods Receiving Expense
A1: Goods Receiving
G2: Delivey Person's Expense
A3: Date | B3: TO No. | C3: Customer Name | D3: Volume (L) | E3: Labour Cost | F3: Transport Cost | G3: Helper Name | H3: Helper Conveyance | I3: Hotel Rent | J3: Food | K3: Others | L3: Total
D4: =SUM(D5:D101) -> 240 | E4: =SUM(E5:E101) -> 0 | F4: =SUM(F5:F101) -> 300 | H4: =SUM(H5:H101) -> 40 | I4: =SUM(I6:I101) -> 0 | J4: =SUM(J5:J101) -> 0 | K4: =SUM(K6:K101) -> 0 | L4: =SUM(E4,F4,H4,I4,J4,K4) -> 340
A5: 46033 | B5: 10912 | C5: cumilla depot | D5: 240 | F5: 300 | G5: rafi | H5: 40

Sheet 6.WH-Depot Maintenance
B1: WH/Depot Maintenance
C3: Total | D3: =SUM(D5:D37) -> 400
A4: Date | B4: Description | C4: Purpose | D4: Amount | E4: Remarks
A5: 46034 | B5: courier | C5: depot | D5: 100
A6: 46034 | B6: courier | C6: depot | D6: 200
A7: 46035 | B7: courier | C7: depot | D7: 100

Sheet 7. Utilities
B1: Utilities Expense
C2: Total | F2: =SUM(F4:F5) -> 772
A3: Date | B3: Utility Type | C3: Billing Month | F3: Amount | G3: Remarks
A4: 1/12/2025 to 14/1/2026 | B4: Electricity bill | C4: 46023 | D4: Previous unit-3229,current unit-3325 | E4: 96 unit | F4: 672 | G4: one month
A5: 1-12-2025 T0 31-12-2025 | B5: water bill | C5: 46023 | F5: 100 | G5: one month
F11: Received
B22: Utilities Expense
C23: Total | F23: =SUM(F25:F26) -> 772
A24: Date | B24: Utility Type | C24: Billing Month | F24: Amount | G24: Remarks
A25: 1/12/2025 to 14/1/2026 | B25: Electricity bill | C25: 46023 | D25: Previous unit-3229,current unit-3325 | E25: 96 unit | F25: 672 | G25: one month
A26: 1-12-2025 T0 31-12-2025 | B26: water bill | C26: 46023 | F26: 100 | G26: one month
F32: Received

Sheet 8. Printing
A1: Printing Expense
D2: Total | E2: =SUM(E4:E25) -> 0
A3: Date | B3: Description | C3: Purpose | D3: Qty | E3: Amount | F3: Remarks

Sheet 9. Stationary
B1: Stationary Expense
D2: Total | E2: =SUM(E4:E23) -> 0
A3: Date | B3: Description | C3: Purpose | D3: Qty | E3: Amount | F3: Remarks

Sheet 10-11.Delivery Van Expense
A1: Delivery Van Fuel & Lubricants
C2: Total | D2: =SUM(D4:D9) -> 0
A3: Date | B3: Desription | C3: Qty | D3: Amount | E3: Remarks
A12: Delivery Van Maintenance
C13: Total | D13: =SUM(D15:D25) -> 0
A14: Date | B14: Desription | C14: Qty | D14: Amount | E14: Remarks

Sheet 12. Entertainment
A1: Entertainment
C2: Total | D2: =SUM(D4:D16) -> 0
A3: Date | B3: Description | C3: Purpose | D3: Amount | E3: Remarks

Sheet 13. Food Allowance
A1: Food Allowance
C2: Total | D2: =SUM(D4:D30) -> 0
A3: Duration/Date | B3: Employee Name | C3: Day | D3: Amount | E3: Remarks

Sheet 14. Conveyance
A1: Conveyance
C2: Total | D2: =SUM(D4:D36) -> 50
A3: Duration/Date | B3: Employee Name | C3: Purpose | D3: Amount | E3: Remarks
A4: 46036 | B4: sohel | C4: depot | D4: 50
C13: S

Sheet 15. For Security
A1: Holiday working bill
C2: Total | D2: =SUM(D4:D30) -> 2200
A3: Date | B3: Employee Name | C3: Purpose | D3: Amount | E3: Remarks
A4: 46387 | B4: sohel ahmed | C4: depot | D4: 800 | E4: We are working on a government holiday.
A5: 46387 | B5: arif khan | C5: depot | D5: 800
A6: 46387 | B6: shah alam | C6: depot | D6: 300
A7: 46387 | B7: rafi patahn | C7: depot | D7: 300

Sheet Monthly Volume
W1: Daily Basis Delivered & Received Volume (L)
B2: Month Name:
B3: Item | C3: 1 | D3: 2 | E3: 3 | F3: 4 | G3: 5 | H3: 6 | I3: 7 | J3: 8 | K3: 9 | L3: 10 | M3: 11 | N3: 12 | O3: 13 | P3: 14 | Q3: 15 | R3: 16 | S3: 17 | T3: 18 | U3: 19 | V3: 20 | W3: 21 | X3: 22 | Y3: 23 | Z3: 24 | AA3: 25 | AB3: 26 | AC3: 27 | AD3: 28 | AE3: 29 | AF3: 30 | AG3: 31 | AH3: Total
B4: B2B IPP | AH4: =SUM(C4:AG4) -> 0
B5: B2C
B6: B2B- Non Power
B7: Goods Transfer (Sending)
B8: Goods Transfer (Received)
C9: =SUM(C4:C8) -> 0 | D9: =SUM(D4:D8) -> 0 | E9: =SUM(E4:E8) -> 0 | F9: =SUM(F4:F8) -> 0 | G9: =SUM(G4:G8) -> 0 | H9: =SUM(H4:H8) -> 0 | I9: =SUM(I4:I8) -> 0 | J9: =SUM(J4:J8) -> 0 | ... Q9: =SUM(Q4:Q8) -> 0

Sheet Purchase Voucher
A1: Ranks Petroleum Limited | G1: Ranks Petroleum Limited
A3: WH/Depot Name: | C3: Bogura | G3: WH/Depot Name:Cumilla
A5: Sl. No. | B5: Date | C5: Description | D5: Qty | E5: Amount | G5: Sl. No. | H5: Date | I5: Description | J5: Qty | K5: Amount
A6: 1 | G6: 1
A7: 2
A8: 3 | G8: Total
A9: 4
A10: 5
A11: 6 | G11: …................. | I11: …..................... | J11: …......................
A12: Total | E12: =SUM(E6:E11) -> 0 | G12: Prepared By | I12: In-charge | J12: Checked By
A15: …................. | C15: …..................... | D15: …...................... | G15: Ranks Petroleum Limited
A16: Prepared By | C16: In-charge | D16: Checked By
G17: WH/Depot Name:
A19: Ranks Petroleum Limited | G19: Sl. No. | H19: Date | I19: Description | J19: Qty | K19: Amount
G20: 1
A21: WH/Depot Name: | G21: 2
G22: 3
A23: Sl. No. | B23: Date | C23: Description | D23: Qty | E23: Amount | G23: 4
A24: 1 | G24: 5
A25: 2 | G25: 6
A26: 3 | G26: Total
A27: 4
A28: 5
A29: 6
A30: Total | G30: …................. | I30: …..................... | J30: …......................
G31: Prepared By | I31: In-charge | J31: Checked By
A34: …................. | C34: …..................... | D34: …......................
A35: Prepared By | C35: In-charge | D35: Checked By

Sheet Labour Bill Voucher
A1: Ranks Petroleum Limited | H1: Ranks Petroleum Limited
C2: Labour Bill | J2: Food Bill After Work
A3: Sl. No. | B3: Date | C3: TO Number | D3: Purpose | E3: Amount | F3: Labour Signature | H3: Sl. No. | I3: Date | J3: Description | K3: Purpose | L3: Amount | M3: Remaks
A4: 1 | B4: 45327 | C4: 7791 | D4: Unloading | E4: 200 | H4: 1 | I4: 45326 | J4: delivery | K4: depot | L4: 200 | M4: 3 person food
A5: 2 | B5: 45328 | C5: 7795 | D5: Unloading | E5: 20 | H5: 2 | I5: 45327 | J5: delivery | K5: depot | L5: 200 | M5: 3 person food
D6: Total | E6: =SUM(E4:E5) -> 220 | K6: Total | L6: =SUM(L4:L5) -> 400
A9: …................. | D9: …..................... | F9: …...................... | H9: …................. | K9: …..................... | M9: …......................
A10: Prepared By | D10: In-charge | F10: Checked By | H10: Prepared By | K10: In-charge | M10: Checked By
H12: Ranks Petroleum Limited
A13: Ranks Petroleum Limited | J13: Expense for Security Purpose
C14: Food Bill After Work
A15: Sl. No. | B15: Date | C15: Description | D15: Purpose | E15: Amount | F15: Remaks | H15: Date | J15: Employee Name | K15: purpose | L15: Amount
A16: 1 | B16: 45327 | C16: unloading | D16: depot | E16: 200 | F16: 5 person food
D18: Total | E18: =SUM(E16:E16) -> 200 | K18: Total | L18: 500
A21: …................. | D21: …..................... | F21: …......................
A22: Prepared By | D22: In-charge | F22: Checked By | H22: …................. | J22: …..................... | L22: …......................
H23: Prepared By | J23: In-charge | L23: Checked By
A27: Holiday TA/DA Bill of Management Employee
A28: Employee Name: Sohel Ahmed | E28: Employee ID: | F28: 150362
A29: Designation: Executive | E29: Dept: | F29: Supply Chain
A30: Purpose: Holiday Duty/Outside Duty.
A31: SL. No. | B31: Date | C31: Item | D31: From | E31: To | F31: Via | G31: Amount (BDT)
A32: 1 | C32: TA
A33: 2 | B33: 31.12.25 | D33: Holiday Duty (Year Closing) | G33: 800
A34: Total | G34: =SUM(G32:G33) -> 800
A37: Claimed By | D37: WH Incharge | F37: Line Manager
A41: Holiday TA/DA Bill of Non-management Employee
A42: Employee Name: Arifur Rahman Khan | E42: Employee ID: | F42: 150421
A43: Designation: Executive | E43: Dept: | F43: Supply Chain
A44: Purpose: Holiday Duty/Outside Duty.
A45: SL. No. | B45: Date | C45: Item | D45: From | E45: To | F45: Via | G45: Amount (BDT)
A46: 1 | C46: TA
A47: 2 | B47: 31.12.25 | D47: Holiday Duty (Year Closing) | G47: 800
A48: Total | G48: =SUM(G46:G47) -> 800
A51: Claimed By | D51: WH Incharge | F51: Line Manager
A55: Holiday TA/DA Bill of Non-management Employee
A56: Employee Name: Rafi Pathan | E56: Employee ID: | F56: 150524
A57: Designation: Helper | E57: Dept: | F57: Supply Chain
A58: Purpose: Holiday Duty/Outside Duty.
A59: SL. No. | B59: Date | C59: Item | D59: From | E59: To | F59: Via | G59: Amount (BDT)
...

Sheet Others & Cleaning
A1: Bill (Others) | F1: Cleaning Bill
A2: Bogra Depot | F2: Bogra Depot
A4: SL. No. | B4: Date | C4: Description | D4: Amount (BDT)
A5: 1
A6: 2 | F6: SL. No. | G6: Date | H6: Description | I6: Amount (BDT)
A7: 3 | F7: 1
A8: 4 | F8: 2
A9: 5 | F9: 3
A10: 5 | F10: 4
A11: 6 | F11: 5
A12: 7 | F12: Total
A13: Total | D13: =SUM(D5:D12) -> 0
B15: Note: | C15: For cctv camera wiring
A16: Electrician Name: | B16: Md. Tariqul
A17: Mobile No: | B17: 01796431852
F18: Service Provider Name: | H18: Rahim
A20: Depot Incharge | C20: Line Manager
F22: Depot Incharge | H22: Line Manager
A23: Bill (Others)
A24: Bogra Depot
A26: SL. No. | B26: Date | C26: Description | D26: Amount (BDT)
A27: 1 | B27: 44927 | C27: Van hire to bring furniture | D27: 200
A28: 2
A29: 3
A30: 4
A31: 5
A32: 6
A33: 7
A34: Total | D34: =SUM(D27:D33) -> 200
A38: Van Driver Name: | B38: Abdur Rahim
A39: Mobile No: | B39: 01942-743481
A45: Depot Incharge | C45: Line Manager

Sheet Food Bill
A1: Food Bill (After Hours ) | H1: Food Bill (After Hours / Holiday)
A2: Bogra Depot | H2: Bogra Depot
H4: SL. No. | I4: Date | J4: Name | K4: Time | L4: Description | M4: Amount (BDT)
H5: 1
A6: SL. No. | B6: Date | C6: Name | D6: Time | E6: Description | F6: Amount (BDT) | H6: 2
A7: 1 | H7: Total
A8: 2
A9: Total
B14: Employee | D14: Depot Incharge | F14: Line Manager | H14: Employee | J14: Depot Incharge | M14: Line Manager
