Workbook
Name xadd1: 'Conveyance Voucher'!#REF!

Sheet Front Page
A1: Ranks Petroleum Limited
A2: Petty Cash Bill Breakdown | C2: Bill Duration | D2: 1.01.2026- 10.01.2026
A3: WH/Depot | B3: Cumilla | C3: Month: Jan-2026 | D3: Bill No: Cum/104/jan'2026
A4: Sl. No. | B4: Purpose | C4: Amount (Tk.) | D4: Purpose
A5: 1 | B5: B2B- IPP | C5: ='1. B2B- IPP'!M4 -> 0
A6: 2 | B6: B2C | C6: ='2. B2C'!L4 -> 17610 | D6: Cost: Transport,,Food,Conveyance
A7: 3 | B7: B2B- Non Power | C7: ='3. B2B-Non Power'!L4 -> 0
A8: 4 | B8: Goods Transfer (Sending) | C8: ='4. Goods Sending Expense'!L4 -> 2310 | D8: Cost: Conveyance,food
A9: 5 | B9: Goods Transfer (Receiving) | C9: ='5. Goods Receiving Expense'!L4 -> 700 | D9: Cost: Conveyance,food
A10: 6 | B10: Warehouse Maintenance | C10: ='6.WH-Depot Maintenance'!D3 -> 1450 | D10: courier,labour bill
A11: 7 | B11: Utilities | C11: ='7. Utilities'!F2 -> 0
A12: 8 | B12: Printing | C12: ='8. Printing'!E2 -> 0
A13: 9 | B13: Stationary | C13: ='9. Stationary'!E2 -> 480 | D13: Leger Book
A14: 10 | B14: Delivery Van Fuel & Lubricant | C14: ='10-11.Delivery Van Expense'!D2 -> 0
A15: 11 | B15: Delivery Van Maintenance | C15: ='10-11.Delivery Van Expense'!D13 -> 0
A16: 12 | B16: Entertainment | C16: ='12. Entertainment'!D2 -> 0
A17: 13 | B17: Food Allowance | C17: ='13. Food Allowance'!D2 -> 0
A18: 14 | B18: Conveyance | C18: ='14. Conveyance'!D2 -> 150 | D18: WH to WH, WH to HO, WH to Shop etc.
A19: 15 | B19: Security | C19: ='15. For Security'!D2 -> 0
B20: Total | C20: =SUM(C5:C19) -> 22700
C22: Unit | D22: Litre (L)
C23: B2B-IPP | D23: ='1. B2B- IPP'!D4 -> 0
C24: B2C | D24: ='2. B2C'!D4 -> 11631
C25: B2B-Non Power | D25: ='3. B2B-Non Power'!D4 -> 0
C26: Goods Transfer (Sending) | D26: ='4. Goods Sending Expense'!D4 -> 265
C27: Goods Import (Receiving) | D27: ='5. Goods Receiving Expense'!D4 -> 5143
C28: Total (L) | D28: =SUM(D23:D27) -> 17039
A37: Prepared By | B37: Checked By | C37: Line Manager | D37: Head of SCM
C43: _______________
A44: Dept. of F&A | C44: Internal Audit | D44: Approved By

Sheet 1. B2B- IPP
C1: B2B - IPP
H2: Delivey Person's Expense
A3: Date | B3: DO No. | C3: Customer Name | D3: Volume (L) | E3: Delivery Vehicle Charge (Tk.) | F3: Courier Charge (Tk.) | G3: Labour Charge | H3: Helper Name | I3: Conveyance | J3: Hotel Rent | K3: Food | L3: Others | M3: Total
D4: =SUM(D5:D100) -> 0 | E4: =SUM(E5:E100) -> 0 | F4: =SUM(F5:F100) -> 0 | G4: =SUM(G5:G100) -> 0 | H4: =SUM(H5:H100) -> 0 | I4: =SUM(I5:I100) -> 0 | J4: =SUM(J5:J100) -> 0 | K4: =SUM(K5:K100) -> 0 | L4: =SUM(L5:L100) -> 0 | M4: =SUM(E4,F4,G4,I4,J4,K4,L4) -> 0

Sheet 2. B2C
A1: B2C
G2: Delivey Person's Expense
A3: Date | B3: DO No. | C3: Customer Name | D3: Volume (L) | E3: Labour Cost | F3: Transport Cost | G3: Executive & Helper Name | H3: Helper Conveyance | I3: Hotel Rent | J3: Food | K3: Others | L3: Total
D4: =SUM(D5:D99) -> 11631 | E4: =SUM(E5:E14) -> 100 | F4: =SUM(F5:F99) -> 15770 | H4: =SUM(H5:H99) -> 1340 | I4: =SUM(I6:I14) -> 0 | J4: =SUM(J5:J112) -> 400 | K4: =SUM(K6:K14) -> 0 | L4: =SUM(E4,F4,H4,I4,J4,) -> 17610
A5: 46023 | B5: 097464 | C5: Jogajog Automobiles | D5: 2000 | E5: 100 | F5: 3800 | G5: shah alam & rafi | J5: 200 | L5: =SUM(F5:H5) -> 3800
A6: 46023 | B6: 097506 | C6: M/S MA MOTORS | D6: 156 | L6: =SUM(F6:H6) -> 0
A7: 46025 | B7: 097590 | C7: M/S MA MOTORS | D7: 3800 | F7: 1800 | G7: shah alam & rafi | L7: =SUM(F7:H7) -> 1800
A8: 46026 | B8: 097252 | C8: M A Enterprise | D8: 160 | F8: 1450 | G8: shah alam | H8: 300 | L8: =SUM(F8:H8) -> 1750
A9: 46026 | B9: 097381 | C9: M/S Shava Engineering Automobile | D9: 72 | L9: =SUM(F9:H9) -> 0
A10: 46027 | B10: 097464 | C10: Jogajog Automobiles | D10: 1900 | F10: 3800 | G10: shal alam & rafi | J10: 200 | L10: =SUM(F10:H10) -> 3800
A11: 46027 | B11: 97702 | C11: Rubel Honda Servicing | D11: 27 | F11: 100 | G11: shah alam | H11: 200 | L11: =SUM(F11:H11) -> 300
A12: 46027 | B12: 97718 | C12: Maa harisa parts stor | D12: 13 | L12: =SUM(F12:H12) -> 0
A13: 46027 | B13: 097506 | C13: M/S MA MOTORS | D13: 2700 | F13: 1700 | G13: shah alam & rafi | L13: =SUM(F13:H13) -> 1700
A14: 46027 | B14: 97708 | C14: M/S MA MOTORS | D14: 16 | L14: =SUM(F14:H14) -> 0
A15: 46027 | B15: 97722 | C15: M/S MA MOTORS | D15: 81 | L15: =SUM(F15:H15) -> 0
A16: 46028 | B16: 097787 | C16: Alam Brothers | D16: 18 | F16: 200 | G16: shah alam | H16: 180 | L16: =SUM(F16:H16) -> 380
A17: 46028 | B17: 097571 | C17: Mayar Dowa Motors | D17: 11 | F17: 250 | G17: rafi | L17: =SUM(F17:H17) -> 250
A18: 46028 | B18: 97757 | C18: Nitol Motors Ltd. | D18: 378 | F18: 350 | G18: shah alam & rafi | H18: 60 | L18: =SUM(F18:H18) -> 410
A19: 46029 | B19: 97861 | C19: Khan Motors Parts | D19: 16 | F19: 970 | G19: shah alam | H19: 240 | L19: =SUM(F19:H19) -> 1210
A20: 46029 | B20: 97803 | C20: Ayesha Auto Mobiles | D20: 82 | L20: =SUM(F20:H20) -> 0
A21: 46030 | B21: 97930 | C21: M/S Modina Motors | D21: 26 | F21: 140 | G21: shah alam | H21: 60 | L21: =SUM(F21:H21) -> 200
A22: 46030 | B22: 97960 | C22: Sami Sadi Engineering | D22: 58 | F22: 250 | G22: shah alam | H22: 100 | L22: =SUM(F22:H22) -> 350
A23: 46032 | B23: 97972 | C23: Takiya motors | D23: 80 | F23: 960 | G23: shah alam | H23: 200 | L23: =SUM(F23:H23) -> 1160
A24: 46032 | B24: 98010 | C24: New Abu Taher Auto | D24: 24 | L24: =SUM(F24:H24) -> 0
A25: 46032 | B25: 098005 | C25: Nur Auto | D25: 13 | L25: =SUM(F25:H25) -> 0
L26: =SUM(F26:H26) -> 0
L46: =SUM(F46+H46) -> 0
L47: =SUM(F47+H47) -> 0
L48: =SUM(F48+H48) -> 0
L49: =SUM(F49+H49) -> 0
L50: =SUM(F50+H50) -> 0
L51: =SUM(F51+H51) -> 0
L52: =SUM(F52+H52) -> 0
L53: =SUM(F53+H53) -> 0
L54: =SUM(F54+H54) -> 0

Sheet Goods Delivery Voucher
A1: Ranks Petroleum Limited | I1: Ranks Petroleum Limited
A3: Employee Name: | C3: rafi,sohel,arif,shah alam | F3: Position: | G3: Helper | I3: Employee Name: | K3: Palash | N3: Position: | O3: Helper
A5: Sl. No. | B5: Date | C5: From | D5: To | E5: Purpose/DO | F5: Via | G5: Amount | I5: Sl. No. | J5: Date | K5: From | L5: To | M5: Purpose/DO | N5: Via | O5: Amount
A6: 1 | B6: 46023 | C6: depot | D6: Ashfak plaza, 768 main road, maijdee bazar, Noakhali,MOZUMDER MARKET PODDAR BAZAR BISHO ROAD | E6: delivery | F6: truck | G6: 3800
A7: =SUM(A6+1) -> 2 | B7: 46025 | C7: depot | D7: MOZUMDER MARKET PODDAR BAZAR BISHO ROAD | E7: delivery | F7: truck | G7: 1800
A8: =SUM(A7+1) -> 3 | B8: 46026 | C8: depot | D8: Sarail, Vishwa Road, B-Baria ,ashuganj. b baria | E8: delivery | F8: bus auto,cng | G8: 1450
A9: =SUM(A8+1) -> 4 | B9: 46027 | C9: depot | D9: Ashfak plaza, 768 main road, maijdee bazar, Noakhali | E9: delivery | F9: truck | G9: 3800
A10: =SUM(A9+1) -> 5 | B10: 46027 | C10: depot | D10: beside of hi School, kankirhat bazar,senbug,Noakhali | E10: delivery | F10: bus auto,cng | G10: 100
A11: =SUM(A10+1) -> 6 | B11: 46027 | C11: depot | D11: MOZUMDER MARKET PODDAR BAZAR BISHO ROAD | E11: delivery | F11: truck | G11: 1700
A12: =SUM(A11+1) -> 7 | B12: 46028 | C12: depot | D12: Stadium market,Sadar,Chandpur | E12: delivery | F12: bus auto,cng | G12: 200
A13: =SUM(A12+1) -> 8 | B13: 46028 | C13: depot | D13: Bus station, Raipur, Laximpur | E13: delivery | F13: bus auto,cng | G13: 250
A14: =SUM(A13+1) -> 9 | B14: 46028 | C14: depot | D14: Mynamoti Cumilla | E14: delivery | F14: bus auto | G14: 350
A15: =SUM(A14+1) -> 10 | B15: 46029 | C15: depot | D15: Korikandi bazar, Titas, Cumilla,Banshgari Steel Bridge, Bancharampur, B-Baria | E15: delivery | F15: bus auto,cng | G15: 970
A16: 11 | B16: 46030 | C16: depot | D16: suagonj bazar,under Robi tower,sadar dokkhin, Cumilla. | E16: delivery | F16: bus auto,cng | G16: 140
A17: =SUM(A15+1) -> 11 | B17: 46030 | C17: depot | D17: Gowripur Bus stand, daudkandi, comilla | E17: delivery | F17: bus auto,cng | G17: 250
A18: 12 | B18: 46032 | C18: depot | D18: Bilbari,Hajigonj, Chandpur,Chatkhil bazar, Chatkhil, Noakhali | E18: delivery | F18: bus auto,cng | G18: 960
F20: Total | G20: =SUM(G6:G18) -> 15770
I22: …................. | L22: …..................... | N22: …......................
I23: Prepared By | L23: In-charge | N23: Checked By
A24: …................. | D24: …..................... | F24: …......................
A25: Prepared By | D25: In-charge | F25: Checked By

Sheet Conveyance Voucher
A1: Ranks Petroleum Limited | I1: Ranks Petroleum Limited
A3: Employee Name: | C3: shah alam & sohel & rafi | F3: Position: | G3: Helper | I3: Employee Name: | K3: arif | N3: Position: | O3: Executive
A5: Sl. No. | B5: Date | C5: From | D5: To | E5: Purpose | F5: Via | G5: Amount | I5: Sl. No. | J5: Date | K5: From | L5: To | M5: Purpose | N5: Via | O5: Amount
A6: 1 | B6: 46028 | C6: Mynamoti Cumilla | D6: depot | E6: delivery | F6: bus,auto,cng | G6: 60 | I6: 1 | J6: 44964 | K6: shoyagazi,cumilla | L6: depot | M6: delivery | N6: bus,auto | O6: 60
I7: …................. | L7: …..................... | N7: …......................
F8: Total | G8: =SUM(G6:G6) -> 60 | I8: Prepared By | L8: In-charge | N8: Checked By
A10: …................. | D10: …..................... | F10: …...................... | I10: Ranks Petroleum Limited
A11: Prepared By | D11: In-charge | F11: Checked By
I12: Employee Name: | K12: dipok | N12: Position: | O12: Helper
A13: Ranks Petroleum Limited
I14: Sl. No. | J14: Date | K14: From | L14: To | M14: Purpose | N14: Via | O14: Amount
A15: Employee Name: | C15: rafi | F15: Position: | G15: helper | I15: 1 | J15: 45202 | K15: b-bariya,tinlack pir,kosba | L15: depot | M15: delivery | N15: bus,auto,cng
I16: 2 | J16: 45203 | K16: police fari cumilla | L16: depot | M16: delivery | N16: auto
A17: Sl. No. | B17: Date | C17: From | D17: To | E17: Purpose | F17: Via | G17: Amount
D18: depot | E18: delivery | F18: bus,auto | N18: Total
D19: depot | E19: delivery | F19: bus,auto
I21: …................. | L21: …..................... | N21: …......................
I22: Prepared By | L22: In-charge | N22: Checked By
F23: Total | G23: =SUM(G18:G21) -> 0
I25: Ranks Petroleum Limited
A26: …................. | D26: …..................... | F26: …...................... | I26: conveyance
A27: Prepared By | D27: In-charge | F27: Checked By | I27: Employee Name: | K27: arif | N27: Position: | O27: Executive
A29: Ranks Petroleum Limited | I29: Sl. No. | J29: Date | K29: From | L29: To | M29: Purpose | N29: Via | O29: Amount
I30: 1
A31: Employee Name: | C31: shah alam | F31: Position: | G31: Helper | I31: 2
A33: Sl. No. | B33: Date | C33: From | D33: To | E33: Purpose | F33: Via | G33: Amount
A34: 1 | B34: 46026 | C34: ashuganj. b baria | D34: depot | E34: delivery | F34: bus,auto,cng | G34: 300
A35: 2 | B35: 46027 | C35: kankirhat bazar,senbug,Noakhali | D35: depot | E35: delivery | F35: mini bus | G35: 200 | N35: Total | O35: =SUM(O30:O33) -> 0
A36: 3 | B36: 46028 | C36: Stadium market,Sadar,Chandpur | D36: depot | E36: delivery | F36: bus,auto,cng | G36: 180
A37: 4 | B37: 46029 | C37: Steel Bridge, Bancharampur, B-Baria | D37: depot | E37: delivery | F37: bus,auto,cng | G37: 240
A38: 5 | B38: 46030 | C38: suagonj bazar,under Robi tower,sadar dokkhin, Cumilla. | D38: depot | E38: delivery | F38: bus,auto,cng | G38: 60
A39: 6 | B39: 46030 | C39: Gowripur Bus stand, daudkandi, comilla | D39: depot | E39: delivery | F39: bus,auto,cng | G39: 100
A40: 7 | B40: 46032 | C40: Chatkhil bazar, Chatkhil, Noakhali | D40: depot | E40: delivery | F40: bus,auto,cng | G40: 200
F42: Total | G42: =SUM(G34:G40) -> 1280 | I42: …................. | L42: …..................... | N42: …......................
I43: Prepared By | L43: In-charge | N43: Checked By
A45: …................. | D45: …..................... | F45: …......................
A46: Prepared By | D46: In-charge | F46: Checked By
A48: Ranks Petroleum Limited
A50: Employee Name: | C50: arif | F50: Position: | G50: Executive
A52: Sl. No. | B52: Date | C52: From | D52: To | E52: Purpose | F52: Via | G52: Amount
...

Sheet 4. Goods Sending Expense
A1: Goods Transfer_Sending
G2: Delivey Person's Expense
A3: Date | B3: TO No. | C3: Customer Name | D3: Volume (L) | E3: Labour Cost | F3: Transport Cost | G3: Helper Name | H3: Helper Conveyance | I3: Hotel Rent | J3: Food | K3: Others | L3: Total
D4: =SUM(D5:D100) -> 265 | E4: =SUM(E5:E100) -> 1930 | F4: =SUM(F5:F100) -> 300 | H4: =SUM(H5:H100) -> 80 | I4: =SUM(I5:I100) -> 0 | J4: =SUM(J5:J100) -> 0 | K4: =SUM(K5:K100) -> 0 | L4: =SUM(E4,F4,H4,I4,J4,K4) -> 2310
A5: 46028 | B5: 10870 | C5: Khulna depot | D5: 40 | E5: 480 | F5: 300 | G5: rafi & sohel | H5: 80
A6: 46028 | B6: 10892 | C6: chattagram warehouse | D6: 225 | E6: 1450

Sheet 3. B2B-Non Power
A1: B2B Non Power
G2: Delivey Person's Expense
A3: Date | B3: DO No. | C3: Customer Name | D3: Volume (L) | E3: Labour Cost | F3: Transport Cost | G3: Helper Name | H3: Helper Conveyance | I3: Hotel Rent | J3: Food | K3: Others | L3: Total
D4: =SUM(D5:D100) -> 0 | E4: =SUM(E5:E100) -> 0 | F4: =SUM(F5:F100) -> 0 | H4: =SUM(H5:H100) -> 0 | I4: =SUM(I5:I100) -> 0 | J4: =SUM(J5:J100) -> 0 | K4: =SUM(K5:K100) -> 0 | L4: =SUM(H4:K4,F4,E4) -> 0

Sheet 5. Goods Receiving Expense
A1: Goods Receiving
G2: Delivey Person's Expense
A3: Date | B3: TO No. | C3: Customer Name | D3: Volume (L) | E3: Labour Cost | F3: Transport Cost | G3: Helper Name | H3: Helper Conveyance | I3: Hotel Rent | J3: Food | K3: Others | L3: Total
D4: =SUM(D5:D101) -> 5143 | E4: =SUM(E5:E101) -> 700 | F4: =SUM(F5:F101) -> 0 | H4: =SUM(H5:H101) -> 0 | I4: =SUM(I6:I101) -> 0 | J4: =SUM(J5:J101) -> 0 | K4: =SUM(K6:K101) -> 0 | L4: =SUM(E4,F4,H4,I4,J4,K4) -> 700
A5: 46025 | B5: 10870 | C5: cumilla depot | D5: 5143 | E5: 700 | G5: sarif & saiful

Sheet 6.WH-Depot Maintenance
B1: WH/Depot Maintenance
C3: Total | D3: =SUM(D4:D38) -> 1450
A4: Date | B4: Description | C4: Purpose | D4: Amount | E4: Remarks
A5: 46023 | B5: rope | C5: depot | D5: 120
A6: 46025 | B6: one day labour bill | C6: depot | D6: 400
A7: 46027 | B7: one day labour bill | C7: depot | D7: 400
A8: 46028 | B8: courier | C8: depot | D8: 150 | E8: gift
A9: 45663 | B9: courier | C9: depot | D9: 150 | E9: gift
A10: 45663 | B10: courier | C10: depot | D10: 100
A11: 45667 | B11: toilet tissue,koil | C11: depot | D11: 130

Sheet 7. Utilities
B1: Utilities Expense
C2: Total | F2: =SUM(F4:F5) -> 0
A3: Date | B3: Utility Type | C3: Billing Month | F3: Amount | G3: Remarks
A4: 23/12/2023 to 31/1/2023 | B4: Electricity bill | C4: 44957 | D4: Previous unit-935,current unit-1008 | E4: 73 unit | G4: one month
A5: 1-12-2023 T0 1-1-2024 | B5: water bill | C5: 44957 | G5: one month
F9: Received

Sheet 8. Printing
A1: Printing Expense
D2: Total | E2: =SUM(E4:E25) -> 0
A3: Date | B3: Description | C3: Purpose | D3: Qty | E3: Amount | F3: Remarks

Sheet 9. Stationary
B1: Stationary Expense
D2: Total | E2: =SUM(E4:E23) -> 480
A3: Date | B3: Description | C3: Purpose | D3: Qty | E3: Amount | F3: Remarks
A4: 45665 | B4: ledger book | C4: depot | D4: 1 | E4: 480

Sheet 10-11.Delivery Van Expense
A1: Delivery Van Fuel & Lubricants
C2: Total | D2: =SUM(D4:D9) -> 0
A3: Date | B3: Desription | C3: Qty | D3: Amount | E3: Remarks
A12: Delivery Van Maintenance
C13: Total | D13: =SUM(D15:D25) -> 0
A14: Date | B14: Desription | C14: Qty | D14: Amount | E14: Remarks

Sheet 12. Entertainment
A1: Entertainment
C2: Total | D2: =SUM(D4:D16) -> 0
A3: Date | B3: Description | C3: Purpose | D3: Amount | E3: Remarks

Sheet 13. Food Allowance
A1: Food Allowance
C2: Total | D2: =SUM(D4:D30) -> 0
A3: Duration/Date | B3: Employee Name | C3: Day | D3: Amount | E3: Remarks

Sheet 14. Conveyance
A1: Conveyance
C2: Total | D2: =SUM(D4:D36) -> 150
A3: Duration/Date | B3: Employee Name | C3: Purpose | D3: Amount | E3: Remarks
A4: 46028 | B4: sohel | C4: depot | D4: 50 | E4: petty cash bill & nitol motors document
A5: 46029 | B5: rafi | C5: depot | D5: 100 | E5: gift items received
C13: S

Sheet 15. For Security
A1: Expense for Security Purpose
C2: Total | D2: =SUM(D4:D30) -> 0
A3: Date | B3: Employee Name | C3: Purpose | D3: Amount | E3: Remarks

Sheet Monthly Volume
W1: Daily Basis Delivered & Received Volume (L)
B2: Month Name:
B3: Item | C3: 1 | D3: 2 | E3: 3 | F3: 4 | G3: 5 | H3: 6 | I3: 7 | J3: 8 | K3: 9 | L3: 10 | M3: 11 | N3: 12 | O3: 13 | P3: 14 | Q3: 15 | R3: 16 | S3: 17 | T3: 18 | U3: 19 | V3: 20 | W3: 21 | X3: 22 | Y3: 23 | Z3: 24 | AA3: 25 | AB3: 26 | AC3: 27 | AD3: 28 | AE3: 29 | AF3: 30 | AG3: 31 | AH3: Total
B4: B2B IPP | AH4: =SUM(C4:AG4) -> 0
B5: B2C
B6: B2B- Non Power
B7: Goods Transfer (Sending)
B8: Goods Transfer (Received)
C9: =SUM(C4:C8) -> 0 | D9: =SUM(D4:D8) -> 0 | E9: =SUM(E4:E8) -> 0 | F9: =SUM(F4:F8) -> 0 | G9: =SUM(G4:G8) -> 0 | H9: =SUM(H4:H8) -> 0 | I9: =SUM(I4:I8) -> 0 | J9: =SUM(J4:J8) -> 0 | ... Q9: =SUM(Q4:Q8) -> 0

Sheet Purchase Voucher
A1: Ranks Petroleum Limited | G1: Ranks Petroleum Limited
A3: WH/Depot Name: | C3: Bogura | G3: WH/Depot Name:Cumilla
A5: Sl. No. | B5: Date | C5: Description | D5: Qty | E5: Amount | G5: Sl. No. | H5: Date | I5: Description | J5: Qty | K5: Amount
A6: 1 | G6: 1
A7: 2
A8: 3 | G8: Total
A9: 4
A10: 5
A11: 6 | G11: …................. | I11: …..................... | J11: …......................
A12: Total | E12: =SUM(E6:E11) -> 0 | G12: Prepared By | I12: In-charge | J12: Checked By
A15: …................. | C15: …..................... | D15: …...................... | G15: Ranks Petroleum Limited
A16: Prepared By | C16: In-charge | D16: Checked By
G17: WH/Depot Name:
A19: Ranks Petroleum Limited | G19: Sl. No. | H19: Date | I19: Description | J19: Qty | K19: Amount
G20: 1
A21: WH/Depot Name: | G21: 2
G22: 3
A23: Sl. No. | B23: Date | C23: Description | D23: Qty | E23: Amount | G23: 4
A24: 1 | G24: 5
A25: 2 | G25: 6
A26: 3 | G26: Total
A27: 4
A28: 5
A29: 6
A30: Total | G30: …................. | I30: …..................... | J30: …......................
G31: Prepared By | I31: In-charge | J31: Checked By
A34: …................. | C34: …..................... | D34: …......................
A35: Prepared By | C35: In-charge | D35: Checked By

Sheet Labour Bill Voucher
A1: Ranks Petroleum Limited | H1: Ranks Petroleum Limited
C2: Labour Bill | J2: Food Bill After Work
A3: Sl. No. | B3: Date | C3: TO Number | D3: Purpose | E3: Amount | F3: Labour Signature | H3: Sl. No. | I3: Date | J3: Description | K3: Purpose | L3: Amount | M3: Remaks
A4: 1 | B4: 46025 | C4: 10870 | D4: Unloading | E4: 700 | H4: 1 | I4: 46023 | J4: delivery | K4: depot | L4: 200 | M4: 2 person food
A5: 2 | H5: 2 | I5: 46027 | J5: delivery | K5: depot | L5: 200 | M5: 2 person food
D6: Total | E6: =SUM(E4:E5) -> 700 | K6: Total | L6: =SUM(L4:L5) -> 400
A9: …................. | D9: …..................... | F9: …...................... | H9: …................. | K9: …..................... | M9: …......................
A10: Prepared By | D10: In-charge | F10: Checked By | H10: Prepared By | K10: In-charge | M10: Checked By
H12: Ranks Petroleum Limited
A13: Ranks Petroleum Limited | J13: Expense for Security Purpose
C14: Food Bill After Work
A15: Sl. No. | B15: Date | C15: Description | D15: Purpose | E15: Amount | F15: Remaks | H15: Date | J15: Employee Name | K15: purpose | L15: Amount
A16: 1 | B16: 45327 | C16: unloading | D16: depot | E16: 200 | F16: 5 person food
D18: Total | E18: =SUM(E16:E16) -> 200 | K18: Total | L18: 500
A21: …................. | D21: …..................... | F21: …......................
A22: Prepared By | D22: In-charge | F22: Checked By | H22: …................. | J22: …..................... | L22: …......................
H23: Prepared By | J23: In-charge | L23: Checked By
A25: Ranks Petroleum Limited
C26: Labour Bill
A27: Sl. No. | B27: Date | C27: DO Number | D27: Purpose | E27: Amount | F27: Labour Signature
A28: 1 | B28: 46023 | C28: 97464 | D28: Unloading | E28: 100
D30: Total | E30: =SUM(E28:E29) -> 100
A33: …................. | D33: …..................... | F33: …......................
A34: Prepared By | D34: In-charge | F34: Checked By
A37: Ranks Petroleum Limited
C38: Labour Bill
A39: Sl. No. | B39: Date | C39: Description | D39: Purpose | E39: Amount | F39: Remaks
A40: 1 | B40: 46025 | C40: products processing | D40: depot | E40: 400 | F40: The MRP sticker and QR sticker, crasecart are pasted on the carton
A41: 2 | B41: 46027 | C41: products processing | D41: depot | E41: 400
D43: Total | E43: =SUM(E40:E41) -> 800
A46: …................. | D46: …..................... | F46: …......................
A47: Prepared By | D47: In-charge | F47: Checked By

Sheet Others & Cleaning
A1: Bill (Others) | F1: Cleaning Bill
A2: Bogra Depot | F2: Bogra Depot
A4: SL. No. | B4: Date | C4: Description | D4: Amount (BDT)
A5: 1
A6: 2 | F6: SL. No. | G6: Date | H6: Description | I6: Amount (BDT)
A7: 3 | F7: 1
A8: 4 | F8: 2
A9: 5 | F9: 3
A10: 5 | F10: 4
A11: 6 | F11: 5
A12: 7 | F12: Total
A13: Total | D13: =SUM(D5:D12) -> 0
B15: Note: | C15: For cctv camera wiring
A16: Electrician Name: | B16: Md. Tariqul
A17: Mobile No: | B17: 01796431852
F18: Service Provider Name: | H18: Rahim
A20: Depot Incharge | C20: Line Manager
F22: Depot Incharge | H22: Line Manager
A23: Bill (Others)
A24: Bogra Depot
A26: SL. No. | B26: Date | C26: Description | D26: Amount (BDT)
A27: 1 | B27: 44927 | C27: Van hire to bring furniture | D27: 200
A28: 2
A29: 3
A30: 4
A31: 5
A32: 6
A33: 7
A34: Total | D34: =SUM(D27:D33) -> 200
A38: Van Driver Name: | B38: Abdur Rahim
A39: Mobile No: | B39: 01942-743481
A45: Depot Incharge | C45: Line Manager

Sheet Food Bill
A1: Food Bill (After Hours ) | H1: Food Bill (After Hours / Holiday)
A2: Bogra Depot | H2: Bogra Depot
H4: SL. No. | I4: Date | J4: Name | K4: Time | L4: Description | M4: Amount (BDT)
H5: 1
A6: SL. No. | B6: Date | C6: Name | D6: Time | E6: Description | F6: Amount (BDT) | H6: 2
A7: 1 | H7: Total
A8: 2
A9: Total
B14: Employee | D14: Depot Incharge | F14: Line Manager | H14: Employee | J14: Depot Incharge | M14: Line Manager
