Workbook
Name xadd1: 'Conveyance Voucher'!#REF!

Sheet Front Page
A1: Ranks Petroleum Limited
A2: Petty Cash Bill Breakdown | C2: Bill Duration | D2: 01.02.2026- 10.02.2026
A3: WH/Depot | B3: Cumilla | C3: Month: February-2026 | D3: Bill No: Cum/107/February'2026
A4: Sl. No. | B4: Purpose | C4: Amount (Tk.) | D4: Purpose
A5: 1 | B5: B2B- IPP | C5: ='1. B2B- IPP'!M4 -> 0
A6: 2 | B6: B2C | C6: ='2. B2C'!L4 -> 24350 | D6: Cost: Transport,,Food,Conveyance
A7: 3 | B7: B2B- Non Power | C7: ='3. B2B-Non Power'!L4 -> 0
A8: 4 | B8: Goods Transfer (Sending) | C8: ='4. Goods Sending Expense'!L4 -> 1890 | D8: Cost: Conveyance,food
A9: 5 | B9: Goods Transfer (Receiving) | C9: ='5. Goods Receiving Expense'!L4 -> 990 | D9: Cost: Conveyance,food
A10: 6 | B10: Warehouse Maintenance | C10: ='6.WH-Depot Maintenance'!D3 -> 1200 | D10: courier
A11: 7 | B11: Utilities | C11: ='7. Utilities'!F2 -> 0
A12: 8 | B12: Printing | C12: ='8. Printing'!E2 -> 0
A13: 9 | B13: Stationary | C13: ='9. Stationary'!E2 -> 2040 | D13: A 4Paper,pin,rabar,gum gtab,marker Pen
A14: 10 | B14: Delivery Van Fuel & Lubricant | C14: ='10-11.Delivery Van Expense'!D2 -> 0
A15: 11 | B15: Delivery Van Maintenance | C15: ='10-11.Delivery Van Expense'!D13 -> 0
A16: 12 | B16: Entertainment | C16: ='12. Entertainment'!D2 -> 0
A17: 13 | B17: Food Allowance | C17: ='13. Food Allowance'!D2 -> 0
A18: 14 | B18: Conveyance | C18: ='14. Conveyance'!D2 -> 750 | D18: WH to WH, WH to HO, WH to Shop etc.
A19: 15 | B19: Security | C19: ='15. For Security'!D2 -> 0
B20: Total | C20: =SUM(C5:C19) -> 31220
C22: Unit | D22: Litre (L)
C23: B2B-IPP | D23: ='1. B2B- IPP'!D4 -> 0
C24: B2C | D24: ='2. B2C'!D4 -> 4646
C25: B2B-Non Power | D25: ='3. B2B-Non Power'!D4 -> 0
C26: Goods Transfer (Sending) | D26: ='4. Goods Sending Expense'!D4 -> 170
C27: Goods Import (Receiving) | D27: ='5. Goods Receiving Expense'!D4 -> 8160
C28: Total (L) | D28: =SUM(D23:D27) -> 12976
A37: Prepared By | B37: Checked By | C37: Line Manager | D37: Head of SCM
C43: _______________
A44: Dept. of F&A | C44: Internal Audit | D44: Approved By

Sheet 1. B2B- IPP
C1: B2B - IPP
H2: Delivey Person's Expense
A3: Date | B3: DO No. | C3: Customer Name | D3: Volume (L) | E3: Delivery Vehicle Charge (Tk.) | F3: Courier Charge (Tk.) | G3: Labour Charge | H3: Helper Name | I3: Conveyance | J3: Hotel Rent | K3: Food | L3: Others | M3: Total
D4: =SUM(D5:D100) -> 0 | E4: =SUM(E5:E100) -> 0 | F4: =SUM(F5:F100) -> 0 | G4: =SUM(G5:G100) -> 0 | H4: =SUM(H5:H100) -> 0 | I4: =SUM(I5:I100) -> 0 | J4: =SUM(J5:J100) -> 0 | K4: =SUM(K5:K100) -> 0 | L4: =SUM(L5:L100) -> 0 | M4: =SUM(E4,F4,G4,I4,J4,K4,L4) -> 0

Sheet 2. B2C
A1: B2C
G2: Delivey Person's Expense
A3: Date | B3: DO No. | C3: Customer Name | D3: Volume (L) | E3: Labour Cost | F3: Transport Cost | G3: Executive & Helper Name | H3: Helper Conveyance | I3: Hotel Rent | J3: Food | K3: Others | L3: Total
D4: =SUM(D5:D88) -> 4646 | E4: =SUM(E6:E100) -> 150 | F4: =SUM(F5:F88) -> 21190 | H4: =SUM(H5:H88) -> 2910 | I4: =SUM(I6:I10) -> 0 | J4: =SUM(J6:J101) -> 100 | K4: =SUM(K6:K10) -> 0 | L4: =SUM(E4,F4,H4,I4,J4,) -> 24350
A5: 46054 | B5: 99014 | C5: B K Traders and Motors Prats | D5: 195 | F5: 4300 | G5: shah alam & rafi | L5: =SUM(F5:H5) -> 4300
A6: 46054 | B6: 99200 | C6: M A Enterprise | D6: 160 | L6: =SUM(F6:H6) -> 0
A7: 46054 | B7: 99201 | C7: M/S Shava Engineering Automobile | D7: 73 | L7: =SUM(F7:H7) -> 0
A8: 46054 | B8: 99192 | C8: Garda Shield Security Serviece Ltd | D8: 44 | L8: =SUM(F8:H8) -> 0
A9: 46055 | B9: 99179 | C9: Jibon Honda Workshop | D9: 157 | F9: 1350 | G9: shah alam & rafi | H9: 350 | J9: 100 | L9: =SUM(F9:H9) -> 1700
A10: 46055 | B10: 99191 | C10: Alauddin Honda Servicing | D10: 39 | L10: =SUM(F10:H10) -> 0
A11: 46055 | B11: 99253 | C11: Abdur Rohim oil Store | D11: 27 | F11: 1050 | G11: shah alam & rafi | H11: 400 | L11: =SUM(F11:H11) -> 1450
A12: 46055 | B12: 99277 | C12: Jogajog automobiles | D12: 208 | L12: =SUM(F12:H12) -> 0
A13: 46055 | B13: 99316 | C13: M/S Ma motors | D13: 180 | F13: 200 | G13: shah alam | H13: 20 | L13: =SUM(F13:H13) -> 220
A14: 46056 | B14: 99343 | C14: Alam brathers | D14: 420 | F14: 1720 | G14: shah alam & rafi | H14: 400 | L14: =SUM(F14:H14) -> 2120
A15: 46056 | B15: 99366 | C15: Motor Mujiam | D15: 4 | L15: =SUM(F15:H15) -> 0
A16: 46056 | B16: 99363 | C16: New Abu Taher Auto | D16: 236 | F16: 970 | G16: shah alam | H16: 200 | L16: =SUM(F16:H16) -> 1170
A17: 46056 | B17: 99367 | C17: Nitol Motors Ltd. | D17: 388 | F17: 380 | G17: shah alam | H17: 30 | L17: =SUM(F17:H17) -> 410
A18: 46056 | B18: 99384 | C18: M/S Modina Motors | D18: 26 | F18: 140 | G18: sohel | H18: 60 | L18: =SUM(F18:H18) -> 200
A19: 46056 | B19: 99390 | C19: Fataha Traders | D19: 4 | F19: 100 | G19: sohel | H19: 100 | L19: =SUM(F19:H19) -> 200
A20: 46058 | B20: 99470 | C20: sotota lubricants | D20: 300 | F20: 1200 | G20: shah alam | L20: =SUM(F20:H20) -> 1200
A21: 46058 | B21: 99477 | C21: M/S Ma motors | D21: 216 | L21: =SUM(F21:H21) -> 0
A22: 46058 | B22: 99456 | C22: Ayesha Auto Mobiles | D22: 80 | F22: 960 | G22: shah alam | H22: 250 | L22: =SUM(F22:H22) -> 1210
A23: 46058 | B23: 99416 | C23: M/S Ma motors | D23: 195 | F23: 180 | G23: shah alam | H23: 20 | L23: =SUM(F23:H23) -> 200
A24: 46060 | B24: 99532 | C24: Monohorkhadi cold storage | D24: 200 | F24: 4400 | G24: shah alam & rafi | L24: =SUM(F24:H24) -> 4400
A25: 46060 | B25: 99465 | C25: Alam brathers | D25: 351 | L25: =SUM(F25:H25) -> 0
A26: 46060 | B26: 99451 | C26: M/S Jononi Motors | D26: 210 | L26: =SUM(F26:H26) -> 0
A27: 46060 | B27: 99533 | C27: M/S Jononi Motors | D27: 31 | L27: =SUM(F27:H27) -> 0
A28: 46061 | B28: 99579 | C28: M/S Ma motors | D28: 29 | F28: 50 | G28: Sohel | H28: 20 | L28: =SUM(F28:H28) -> 70
A29: 46061 | B29: 099410 | C29: M/S Mozahid filling Station | D29: 195 | F29: 1180 | G29: rafi | H29: 300 | L29: =SUM(F29:H29) -> 1480
A30: 46062 | B30: 99547 | C30: Forhad Motors | D30: 16 | F30: 960 | G30: rafi | H30: 220 | L30: =SUM(F30:H30) -> 1180
A31: 46062 | B31: 99556 | C31: Maa Auto Engineering & Service Center | D31: 26 | L31: =SUM(F31:H31) -> 0
A32: 46062 | B32: 99557 | C32: Rasel Motors | D32: 80 | L32: =SUM(F32:H32) -> 0
A33: 46062 | B33: 99563 | C33: M/S Modina Autoz | D33: 27 | F33: 1000 | G33: shah alam | H33: 200 | L33: =SUM(F33:H33) -> 1200
A34: 46062 | B34: 99635 | C34: Arju motors | D34: 24 | L34: =SUM(F34:H34) -> 0
A35: 46062 | B35: 99640 | C35: Jogajog automobiles | D35: 48 | L35: =SUM(F35:H35) -> 0
A36: 46062 | B36: 99666 | C36: Naim Tyre N Lube House | D36: 92 | F36: 120 | G36: rafi | H36: 40 | L36: =SUM(F36+H36) -> 160
A37: 46063 | B37: 99716 | C37: sotota lubricants | D37: 105 | F37: 550 | G37: shah alam | H37: 140 | L37: =SUM(F37+H37) -> 690
A38: 46063 | B38: 99733 | C38: Sm Motors | D38: 13 | F38: 20 | G38: shah alam | H38: 20 | L38: =SUM(F38+H38) -> 40
A39: 46063 | B39: 99759 | C39: M/S Ma motors | D39: 234 | E39: 150 | F39: 230 | G39: sohel | H39: 20 | L39: =SUM(F39+H39) -> 250
A40: 46063 | B40: 099652 | C40: Modina Motors | D40: 13 | F40: 130 | G40: rafi | H40: 120 | L40: =SUM(F40+H40) -> 250
...

Sheet 3. B2B-Non Power
A1: B2B Non Power
G2: Delivey Person's Expense
A3: Date | B3: DO No. | C3: Customer Name | D3: Volume (L) | E3: Labour Cost | F3: Transport Cost | G3: Helper Name | H3: Helper Conveyance | I3: Hotel Rent | J3: Food | K3: Others | L3: Total
D4: =SUM(D5:D100) -> 0 | E4: =SUM(E5:E100) -> 0 | F4: =SUM(F5:F100) -> 0 | H4: =SUM(H5:H100) -> 0 | I4: =SUM(I5:I100) -> 0 | J4: =SUM(J5:J100) -> 0 | K4: =SUM(K5:K100) -> 0 | L4: =SUM(H4:K4,F4,E4) -> 0

Sheet Goods Delivery Voucher
A1: Ranks Petroleum Limited | I1: Ranks Petroleum Limited
A3: Employee Name: | C3: rafi,sohel,arif,shah alam | F3: Position: | G3: Helper | I3: Employee Name: | K3: Palash | N3: Position: | O3: Helper
A5: Sl. No. | B5: Date | C5: From | D5: To | E5: Purpose/DO | F5: Via | G5: Amount | I5: Sl. No. | J5: Date | K5: From | L5: To | M5: Purpose/DO | N5: Via | O5: Amount
A6: 1 | B6: 46054 | C6: depot | D6: Medda. Sadar. b baria,ashuganj. b baria,Sarail, Vishwa Road, B-Baria | E6: delivery | F6: truck | G6: 4300
A7: 2 | B7: 46055 | C7: depot | D7: Raster Matha,Senbagh,Noakhali,College Road,Kobirhat,Noakhali. | E7: delivery | F7: auto/bus/cng | G7: 1350
A8: 3 | B8: 46055 | C8: depot | D8: Chayni bazar,Begumganj, Noakhali,Ashfak plaza,main road Maijdee bazar, Noakhali | E8: delivery | F8: auto/bus/cng | G8: 1050
A9: 4 | B9: 46055 | C9: depot | D9: Mozumder market, poddar bazar bishoroad | E9: delivery | F9: auto | G9: 200
A10: 5 | B10: 46056 | C10: depot | D10: Beside CNG pump,Hajigonj,Chandpur,Stadium market,Sadar, Chandpur | E10: delivery | F10: auto/bus/cng | G10: 1720
A11: 6 | B11: 46056 | C11: depot | D11: Chatkhil bazar, Chatkhil, Noakhali | E11: delivery | F11: auto/bus/cng | G11: 970
A12: 7 | B12: 46056 | C12: depot | D12: Mynamoti Cumilla | E12: delivery | F12: auto/bus/cng | G12: 380
A13: 8 | B13: 46056 | C13: depot | D13: suagonj bazar,under Robi tower,sadar dokkhin, Cumilla. | E13: delivery | F13: auto/bus/cng | G13: 140
A14: 9 | B14: 46056 | C14: depot | D14: Gowripur Bus stand, daudkandi, comilla | E14: delivery | F14: auto/bus/cng | G14: 100
A15: 10 | B15: 46058 | C15: depot | D15: Mozumder market, poddar bazar | E15: delivery | F15: auto | G15: 180
A16: 11 | B16: 46058 | C16: depot | D16: Mozumder market, poddar bazar bishoroad,buchi North bazar,Bagmara road, Lalmai, Cumilla. | E16: delivery | F16: auto/bus/cng | G16: 1200
A17: 12 | B17: 46058 | C17: depot | D17: Banshgari Steel Bridge, Bancharampur, B-Baria | E17: delivery | F17: auto/bus/cng | G17: 960
... A27: 22 | B27: 46063 | C27: depot | D27: Mizan Market, Kuti Chowmohoni | E27: delivery | F27: auto/bus/cng | G27: 130
F30: Total | G30: =SUM(G6:G27) -> 21190
I32: …................. | L32: …..................... | N32: …......................
I33: Prepared By | L33: In-charge | N33: Checked By
A34: …................. | D34: …..................... | F34: …......................
A35: Prepared By | D35: In-charge | F35: Checked By

Sheet Conveyance Voucher
A1: Ranks Petroleum Limited | I1: Ranks Petroleum Limited
A3: Employee Name: | C3: shah alam & sohel & rafi | F3: Position: | G3: Helper | I3: Employee Name: | K3: arif | N3: Position: | O3: Executive
A5: Sl. No. | B5: Date | C5: From | D5: To | E5: Purpose | F5: Via | G5: Amount | I5: Sl. No. | J5: Date | K5: From | L5: To | M5: Purpose | N5: Via | O5: Amount
A6: 1 | B6: 46055 | C6: Raster Matha,Senbagh,Noakhali,College Road,Kobirhat,Noakhali. | D6: depot | E6: delivery | F6: bus,auto,cng | G6: 350 | I6: 1 | J6: 44964 | K6: shoyagazi,cumilla | L6: depot | M6: delivery | N6: bus,auto | O6: 60
A7: 2 | B7: 46055 | C7: Chayni bazar,Begumganj, Noakhali,Ashfak plaza,main road Maijdee bazar, Noakhali | D7: depot | E7: delivery | F7: bus,auto,cng | G7: 400 | N7: Total | O7: =SUM(O6:O6) -> 60
A8: 3 | B8: 46056 | C8: Stadium market,Sadar, Chandpur | D8: depot | E8: delivery | F8: bus,auto,cng | G8: 400
I9: …................. | L9: …..................... | N9: …......................
F10: Total | G10: =SUM(G6:G8) -> 1150 | I10: Prepared By | L10: In-charge | N10: Checked By
A12: …................. | D12: …..................... | F12: …...................... | I12: Ranks Petroleum Limited
A13: Prepared By | D13: In-charge | F13: Checked By
I14: Employee Name: | K14: dipok | N14: Position: | O14: Helper
A15: Ranks Petroleum Limited
I16: Sl. No. | J16: Date | K16: From | L16: To | M16: Purpose | N16: Via | O16: Amount
A17: Employee Name: | C17: rafi | F17: Position: | G17: helper | I17: 1 | J17: 45202 | K17: b-bariya,tinlack pir,kosba | L17: depot | M17: delivery | N17: bus,auto,cng
I18: 2 | J18: 45203 | K18: police fari cumilla | L18: depot | M18: delivery | N18: auto
A19: Sl. No. | B19: Date | C19: From | D19: To | E19: Purpose | F19: Via | G19: Amount
A20: 1 | B20: 46061 | C20: Ashugonj, Brahmanbaria | D20: depot | E20: delivery | F20: bus,auto | G20: 300 | N20: Total
A21: 2 | B21: 46062 | C21: Beside fair service,Kachua,Chandpur. | D21: depot | E21: delivery | F21: bus,auto | G21: 220
B22: 46062 | C22: station road cumilla | D22: depot | E22: delivery | F22: bus,auto | G22: 40
A23: 3 | B23: 46063 | C23: Mizan Market, Kuti Chowmohoni | D23: depot | E23: delivery | F23: bus,auto | G23: 120
I24: Prepared By | L24: In-charge | N24: Checked By
F25: Total | G25: =SUM(G20:G23) -> 680
I27: Ranks Petroleum Limited
A28: …................. | D28: …..................... | F28: …...................... | I28: conveyance
A29: Prepared By | D29: In-charge | F29: Checked By | I29: Employee Name: | K29: arif | N29: Position: | O29: Executive
A31: Ranks Petroleum Limited | I31: Sl. No. | J31: Date | K31: From | L31: To | M31: Purpose | N31: Via | O31: Amount
I32: 1
A33: Employee Name: | C33: shah alam | F33: Position: | G33: Helper | I33: 2
A35: Sl. No. | B35: Date | C35: From | D35: To | E35: Purpose | F35: Via | G35: Amount
A36: 1 | B36: 46055 | C36: Mozumder market, poddar bazar bishoroad | D36: depot | E36: delivery | F36: bus,auto,cng | G36: 20
A37: 2 | B37: 46056 | C37: Chatkhil bazar, Chatkhil, Noakhali | D37: depot | E37: delivery | F37: mini bus | G37: 200 | N37: Total | O37: =SUM(O32:O35) -> 0
A38: 3 | B38: 46056 | C38: Mynamoti Cumilla | D38: depot | E38: delivery | F38: bus,auto,cng | G38: 30
A39: 4 | B39: 46058 | C39: Banshgari Steel Bridge, Bancharampur, B-Baria | D39: depot | E39: delivery | F39: bus,auto,cng | G39: 250
A40: 5 | B40: 46058 | C40: Mozumder market, poddar bazar bishoroad | D40: depot | E40: delivery | F40: bus,auto,cng | G40: 20
A41: 6 | B41: 46062 | C41: Senbug rastarmatha, senbug,Noakhali | D41: depot | E41: delivery | F41: bus,auto,cng | G41: 200
A42: 7 | B42: 46063 | C42: buchi North bazar,Bagmara road, Lalmai, Cumilla. | D42: depot | E42: delivery | F42: bus,auto,cng | G42: 140
D43: depot | E43: delivery | F43: bus,auto,cng | G43: 20
F45: Total | G45: =SUM(G36:G43) -> 880 | I45: …................. | L45: …..................... | N45: …......................
I46: Prepared By | L46: In-charge | N46: Checked By
A48: …................. | D48: …..................... | F48: …......................
...

Sheet 4. Goods Sending Expense
A1: Goods Transfer_Sending
G2: Delivey Person's Expense
A3: Date | B3: TO No. | C3: Customer Name | D3: Volume (L) | E3: Labour Cost | F3: Transport Cost | G3: Helper Name | H3: Helper Conveyance | I3: Hotel Rent | J3: Food | K3: Others | L3: Total
D4: =SUM(D5:D100) -> 170 | E4: =SUM(E5:E100) -> 0 | F4: =SUM(F5:F100) -> 1650 | H4: =SUM(H5:H100) -> 240 | I4: =SUM(I5:I100) -> 0 | J4: =SUM(J5:J100) -> 0 | K4: =SUM(K5:K100) -> 0 | L4: =SUM(E4,F4,H4,I4,J4,K4) -> 1890
A5: 46055 | B5: 11014 | C5: jessore depot | D5: 120 | F5: 1200 | G5: sohel & rafi | H5: 240
A6: 46055 | B6: 11019 | C6: chattagram warehouse | D6: 50 | F6: 450

Sheet 5. Goods Receiving Expense
A1: Goods Receiving
G2: Delivey Person's Expense
A3: Date | B3: TO No. | C3: Customer Name | D3: Volume (L) | E3: Labour Cost | F3: Transport Cost | G3: Helper Name | H3: Helper Conveyance | I3: Hotel Rent | J3: Food | K3: Others | L3: Total
D4: =SUM(D5:D102) -> 8160 | E4: =SUM(E5:E102) -> 850 | F4: =SUM(F5:F102) -> 100 | H4: =SUM(H5:H102) -> 40 | I4: =SUM(I6:I102) -> 0 | J4: =SUM(J5:J102) -> 0 | K4: =SUM(K6:K102) -> 0 | L4: =SUM(E4,F4,H4,I4,J4,K4) -> 990
A5: 46055 | B5: 11013 | C5: cumilla depot | D5: 3518 | E5: 350 | G5: sarif
A6: 46060 | B6: 11027 | C6: cumilla depot | D6: 4392 | E6: 500 | G6: sojon
A7: 46060 | B7: 11026 | C7: cumilla depot | D7: 200
A8: 46060 | B8: 11022 | C8: cumilla depot | D8: 50 | F8: 100 | G8: shah alam | H8: 40

Sheet 6.WH-Depot Maintenance
B1: WH/Depot Maintenance
C3: Total | D3: =SUM(D5:D37) -> 1200
A4: Date | B4: Description | C4: Purpose | D4: Amount | E4: Remarks
A5: 46055 | B5: courier | C5: depot | D5: 1150
A6: 46061 | B6: courier | C6: depot | D6: 50

Sheet 9. Stationary
B1: Stationary Expense
D2: Total | E2: =SUM(E4:E23) -> 2040
A3: Date | B3: Description | C3: Purpose | D3: Qty | E3: Amount | F3: Remarks
A4: 46083 | B4: stapler pin | C4: depot | D4: 4 | E4: 120
A5: 46083 | B5: A4 paper | C5: depot | D5: 4 | E5: 1400
A6: 46083 | B6: marker pen | C6: depot | D6: 3 | E6: 120
A7: 46083 | B7: attendance book | C7: depot | D7: 1 | E7: 160
A8: 46083 | B8: rabar | C8: depot | D8: 2 | E8: 40
A9: 46083 | B9: gum tabe | C9: depot | D9: 4 | E9: 200

Sheet 7. Utilities
B1: Utilities Expense
C2: Total | F2: =SUM(F4:F5) -> 0
A3: Date | B3: Utility Type | C3: Billing Month | F3: Amount | G3: Remarks
A4: 23/12/2023 to 31/1/2023 | B4: Electricity bill | C4: 44957 | D4: Previous unit-935,current unit-1008 | E4: 73 unit | G4: one month
A5: 1-12-2023 T0 1-1-2024 | B5: water bill | C5: 44957 | G5: one month
F9: Received

Sheet 8. Printing
A1: Printing Expense
D2: Total | E2: =SUM(E4:E25) -> 0
A3: Date | B3: Description | C3: Purpose | D3: Qty | E3: Amount | F3: Remarks

Sheet 10-11.Delivery Van Expense
A1: Delivery Van Fuel & Lubricants
C2: Total | D2: =SUM(D4:D9) -> 0
A3: Date | B3: Desription | C3: Qty | D3: Amount | E3: Remarks
A12: Delivery Van Maintenance
C13: Total | D13: =SUM(D15:D25) -> 0
A14: Date | B14: Desription | C14: Qty | D14: Amount | E14: Remarks

Sheet 12. Entertainment
A1: Entertainment
C2: Total | D2: =SUM(D4:D16) -> 0
A3: Date | B3: Description | C3: Purpose | D3: Amount | E3: Remarks

Sheet 13. Food Allowance
A1: Food Allowance
C2: Total | D2: =SUM(D4:D30) -> 0
A3: Duration/Date | B3: Employee Name | C3: Day | D3: Amount | E3: Remarks

Sheet 14. Conveyance
A1: Conveyance
C2: Total | D2: =SUM(D4:D36) -> 750
A3: Duration/Date | B3: Employee Name | C3: Purpose | D3: Amount | E3: Remarks
A4: 46055 | B4: sohel & shah alam | C4: depot | D4: 300 | E4: jacket delivery mirpur
A5: 46056 | B5: sohel | C5: depot | D5: 60 | E5: Stationary
A6: 46058 | B6: arif | C6: depot | D6: 50 | E6: gum tabe
A7: 46061 | B7: sohel | C7: depot | D7: 50 | E7: petty cash bill
A8: 46063 | B8: shah alam | C8: depot | D8: 140 | E8: jacekt received
A9: 46063 | B9: shah alam | C9: depot | D9: 150 | E9: jacket delivery

Sheet 15. For Security
A1: Expense for Security Purpose
C2: Total | D2: =SUM(D4:D30) -> 0
A3: Date | B3: Employee Name | C3: Purpose | D3: Amount | E3: Remarks

Sheet Monthly Volume
W1: Daily Basis Delivered & Received Volume (L)
B2: Month Name:
B3: Item | C3: 1 | D3: 2 | E3: 3 | F3: 4 | G3: 5 | H3: 6 | I3: 7 | J3: 8 | K3: 9 | L3: 10 | M3: 11 | N3: 12 | O3: 13 | P3: 14 | Q3: 15 | R3: 16 | S3: 17 | T3: 18 | U3: 19 | V3: 20 | W3: 21 | X3: 22 | Y3: 23 | Z3: 24 | AA3: 25 | AB3: 26 | AC3: 27 | AD3: 28 | AE3: 29 | AF3: 30 | AG3: 31 | AH3: Total
B4: B2B IPP | AH4: =SUM(C4:AG4) -> 0
B5: B2C
B6: B2B- Non Power
B7: Goods Transfer (Sending)
B8: Goods Transfer (Received)
C9: =SUM(C4:C8) -> 0 | D9: =SUM(D4:D8) -> 0 | E9: =SUM(E4:E8) -> 0 | F9: =SUM(F4:F8) -> 0 | G9: =SUM(G4:G8) -> 0 | H9: =SUM(H4:H8) -> 0 | I9: =SUM(I4:I8) -> 0 | J9: =SUM(J4:J8) -> 0 | ... Q9: =SUM(Q4:Q8) -> 0

Sheet Purchase Voucher
A1: Ranks Petroleum Limited | G1: Ranks Petroleum Limited
A3: WH/Depot Name: | C3: Bogura | G3: WH/Depot Name:Cumilla
A5: Sl. No. | B5: Date | C5: Description | D5: Qty | E5: Amount | G5: Sl. No. | H5: Date | I5: Description | J5: Qty | K5: Amount
A6: 1 | G6: 1
A7: 2
A8: 3 | G8: Total
A9: 4
A10: 5
A11: 6 | G11: …................. | I11: …..................... | J11: …......................
A12: Total | E12: =SUM(E6:E11) -> 0 | G12: Prepared By | I12: In-charge | J12: Checked By
A15: …................. | C15: …..................... | D15: …...................... | G15: Ranks Petroleum Limited
A16: Prepared By | C16: In-charge | D16: Checked By
G17: WH/Depot Name:
A19: Ranks Petroleum Limited | G19: Sl. No. | H19: Date | I19: Description | J19: Qty | K19: Amount
G20: 1
A21: WH/Depot Name: | G21: 2
G22: 3
A23: Sl. No. | B23: Date | C23: Description | D23: Qty | E23: Amount | G23: 4
A24: 1 | G24: 5
A25: 2 | G25: 6
A26: 3 | G26: Total
A27: 4
A28: 5
A29: 6
A30: Total | G30: …................. | I30: …..................... | J30: …......................
G31: Prepared By | I31: In-charge | J31: Checked By
A34: …................. | C34: …..................... | D34: …......................
A35: Prepared By | C35: In-charge | D35: Checked By

Sheet Labour Bill Voucher
A1: Ranks Petroleum Limited | H1: Ranks Petroleum Limited
C2: Labour Bill | J2: Food Bill After Work
A3: Sl. No. | B3: Date | C3: TO Number | D3: Purpose | E3: Amount | F3: Labour Signature | H3: Sl. No. | I3: Date | J3: Description | K3: Purpose | L3: Amount | M3: Remaks
A4: 1 | B4: 46055 | C4: 11013 | D4: Unloading | E4: 350 | H4: 1 | I4: 46055 | J4: delivery | K4: depot | L4: 100 | M4: 2 person food
A5: 2 | B5: 46060 | C5: 11026,11022 | D5: Unloading | E5: 500
D6: Total | E6: =SUM(E4:E5) -> 850 | K6: Total | L6: =SUM(L4:L5) -> 100
A9: …................. | D9: …..................... | F9: …...................... | H9: …................. | K9: …..................... | M9: …......................
A10: Prepared By | D10: In-charge | F10: Checked By | H10: Prepared By | K10: In-charge | M10: Checked By
H12: Ranks Petroleum Limited
A13: Ranks Petroleum Limited | J13: Expense for Security Purpose
C14: Labour Bill
A15: Sl. No. | B15: Date | C15: DO | D15: Purpose | E15: Amount | F15: Remaks | H15: Date | J15: Employee Name | K15: purpose | L15: Amount
A16: 1 | B16: 46063 | C16: 99759 | D16: depot | E16: 150 | F16: product processing labour bill
D18: Total | E18: =SUM(E16:E16) -> 150 | K18: Total | L18: 500
A21: …................. | D21: …..................... | F21: …......................
A22: Prepared By | D22: In-charge | F22: Checked By | H22: …................. | J22: …..................... | L22: …......................
H23: Prepared By | J23: In-charge | L23: Checked By

Sheet Others & Cleaning
A1: Bill (Others) | F1: Cleaning Bill
A2: Bogra Depot | F2: Bogra Depot
A4: SL. No. | B4: Date | C4: Description | D4: Amount (BDT)
A5: 1
A6: 2 | F6: SL. No. | G6: Date | H6: Description | I6: Amount (BDT)
A7: 3 | F7: 1
A8: 4 | F8: 2
A9: 5 | F9: 3
A10: 5 | F10: 4
A11: 6 | F11: 5
A12: 7 | F12: Total
A13: Total | D13: =SUM(D5:D12) -> 0
B15: Note: | C15: For cctv camera wiring
A16: Electrician Name: | B16: Md. Tariqul
A17: Mobile No: | B17: 01796431852
F18: Service Provider Name: | H18: Rahim
A20: Depot Incharge | C20: Line Manager
F22: Depot Incharge | H22: Line Manager
A23: Bill (Others)
A24: Bogra Depot
A26: SL. No. | B26: Date | C26: Description | D26: Amount (BDT)
A27: 1 | B27: 44927 | C27: Van hire to bring furniture | D27: 200
A28: 2
A29: 3
A30: 4
A31: 5
A32: 6
A33: 7
A34: Total | D34: =SUM(D27:D33) -> 200
A38: Van Driver Name: | B38: Abdur Rahim
A39: Mobile No: | B39: 01942-743481
A45: Depot Incharge | C45: Line Manager

Sheet Food Bill
A1: Food Bill (After Hours ) | H1: Food Bill (After Hours / Holiday)
A2: Bogra Depot | H2: Bogra Depot
H4: SL. No. | I4: Date | J4: Name | K4: Time | L4: Description | M4: Amount (BDT)
H5: 1
A6: SL. No. | B6: Date | C6: Name | D6: Time | E6: Description | F6: Amount (BDT) | H6: 2
A7: 1 | H7: Total
A8: 2
A9: Total
B14: Employee | D14: Depot Incharge | F14: Line Manager | H14: Employee | J14: Depot Incharge | M14: Line Manager
